<?xml version="1.0"?>
<robot name="turtlebot_simple" xmlns:xacro="http://ros.org/wiki/xacro">
    <!-- Base link -->
    <link name="base_link">
        <visual>
            <geometry>
                <cylinder length="0.1" radius="0.2"/>
            </geometry>
            <material name="green">
                <color rgba="0.0 1.0 0.0 1.0"/>
            </material>
        </visual>
    </link>

    <!-- Left wheel joint -->
    <joint name="base_to_wheel_left" type="continuous">
        <parent link="base_link"/>
        <child link="wheel_left"/>
        <origin xyz="0.0 0.2 -0.1" rpy="0 0 0"/>
        <axis xyz="0 0 1"/> <!-- Rotational axis for the wheel -->
    </joint>
    <link name="wheel_left">
        <visual>
            <geometry>
                <cylinder length="0.05" radius="0.05"/>
            </geometry>
            <material name="black">
                <color rgba="0.0 0.0 0.0 1.0"/>
            </material>
        </visual>
    </link>

    <!-- Right wheel joint -->
    <joint name="base_to_wheel_right" type="continuous">
        <parent link="base_link"/>
        <child link="wheel_right"/>
        <origin xyz="0.0 -0.2 -0.1" rpy="0 0 0"/>
        <axis xyz="0 0 1"/> <!-- Rotational axis for the wheel -->
    </joint>
    <link name="wheel_right">
        <visual>
            <geometry>
                <cylinder length="0.05" radius="0.05"/>
            </geometry>
            <material name="black">
                <color rgba="0.0 0.0 0.0 1.0"/>
            </material>
        </visual>
    </link>
</robot>
